Workbook

Sheet DESCRIPCION DEL PROYECTO
A1: DESCRIPCION GENERAL DEL PROYECTO
A2: La planta solar fotovoltaica contará con una potencia nominal de 286,8 MW nominales. La planta se encuentra ubicada en un municipio del interior de la Región de Murcia de entre 10.000 y 100.000 habitantes.
A5: La energía eléctrica generada será vertida a la red de transporte, titularidad de la compañía eléctrica Red Eléctrica Española, S.A., a través de las barras de 400 kV de la una Subestación existente.
A7: Usos actuales del suelo: agrícola, fundamentalmente viñedos. Orografía: irregular con pendientes suaves, con zonas de monte bajo cercanas y marcas de escorrentías. Protecciones ambientales: se desconocen. Existencia de otras instalaciones de generación en la zona: varios parques eólicos que evacuan en la misma subestación colectora de REE. Estado actual del proyecto: en fase de tramitación administrativa.
A19: La superficie total empleada para la ejecución y construcción de la planta solar fotovoltaica es de seis millones novecientos veinte y un mil novecientos veintidós (6.921.922) metros cuadrados. El generador fotovoltaico estará compuesto de 180 agrupaciones de 1,59 MW cada una, formado por módulos policristalinos de marcas de reconocido prestigio.
A23: Para la colocación de los paneles fotovoltaicos se opta por un estructura monopoeste de poste hincado, con una inclinación de los paneles respecto al plano horizontal de 24º, ángulo óptimo teniendo en cuenta las sombras y los datos metereológicos de la zona.
A25: La planta fotovoltaica dispondrá de un sistema de monitorización para el control de su funcionamiento a distancia, el cual recibirá todos los datos procedentes de los distribuidores instalados en la planta.
A27: Se instalará un Sistema de Seguridad que protegerá a la instalación fotovoltaica de cualquier intrusión a la misma. Este sistema de seguridad está basado en un circuito cerrado de cámaras de televisión que se instalará a lo largo del perímetro de la instalación fotovoltaica. Con la emisión de todas las cámaras instaladas se tendrá una retransmisión en tiempo real que permitirá detectar cualquier tipo de alarma, y al mismo tiempo descartar las falsas.
A29: La obra Civil necesaria para realizar la instalación fotovoltaica, va encaminada a la nivelación del terreno, y su posterior compactación.
A31: Para poder participar en el mercado diario de energía existirá un el método para la predicción de la generación de energía eléctrica, hora a hora, para el periodo que comprende las siguientes 39 horas, mediante herramientas de predicción numérica meteorológica con un error inferior al 15% de la potencia instalada, para períodos de predicción que cubren las 24 horas del día siguiente.
A33: Dado que la energía eléctrica no es almacenable, para aumentar la gestinabilidad de la planta se plantea la posibilidad de realizar una instalación de almacenamiento de energía mediante baterias a gran escala con una capacidad de almacenamiento de hasta el 20% de la energía generada diaria por la planta.
A35: Según las condiciones de acceso otorgadas por Red Eléctrica de España S.A., se establece el acceso a la Red de transporte en una futura posición de hasta 450 MW, en 400 kV de la subestación perteneciente a REE más cercana. De esta forma el trazado de la Línea de Alta Tensión desde la instalación fotovoltaica, hasta la Subestación de REE será mediante un doble circuito de 132 kV. Para proceder a la nueva posición de hasta 450 MW, que será planificada por la Consejería de Industria de la Región de Murcia, se procederá a la ejecución de una subestación adyacente, según indicaciones de Red Eléctrica de España, S.A.
... A39: La medida de energía la instalación fotovoltaica será realizada en 30 kV, directamente en la red de Alta Tensión interna de la misma. Esta red interna está compuesta de 180 Centros de Transformación de 1,59 MW. La energía producida en baja tensión en continua, será transformada a alterna y elevada a Alta Tensión. La transformación de la corriente se llevará a cabo en 180 Centros de Transformación de 0,4 / 30 kV. Seguidamente se elevará la tensión de 30 kV a 132 kV, para ser transportada, por una línea aérea de aproximadamente 12 kilómetros, hasta la Subestación de REE.

Sheet INSTRUCCIONES
A1: INSTRUCCIONES PARA SU CUMPLIMENTACIÓN
A4: En la primera pestaña se encuentra la descripción general del proyecto sobre el que tiene que emitir sus juicios de experto.
A6: A continuación tiene ya la encuesta en sí.
A8: En todas y cada una de las siguientes pestañas encuentra, de arriba hacia abajo:
A9: 1. La estructura organizativa de los riesgos, una estructura de tres niveles, con una descripción de cada uno de los riesgos y un combo en el que tiene que elegir su opinión en función de la pestaña en la que se encuentre:
A11: - Probabilidad: se valora la probabilidad de que el riesgo ocurra o se presente.
A12: - Impacto sobre el alcance del proyecto: se valora el impacto del riesgo sobre el alcance del proyecto, entendiendo alcance como el objetivo que se persigue con el proyecto y cuya consecución marcará la finalización con éxito del mismo.
A13: - Impacto sobre el coste: se valora el impacto de cada riesgo sobre el coste del proyecto.
A14: - Impacto sobre el plazo: se valora el impacto de cada riesgo sobre el plazo de desarrollo y ejecución del proyecto.
A16: 2. Una comparativa entre riesgos para cada grupo de los riesgos en los tres niveles de la estructura, con un combo en el que tiene que elegir su opinión comparativa de cada riesgo (fila) con el resto de riesgos que conforman el grupo (columna) en función de la pestaña en la que se encuentre:
A18: - Probabilidad: se valora comparativamente entre los riesgos la probabilidad de aparición de un riesgo frente a otro/s riesgos.
A19: - Impacto sobre el alcance del proyecto: se valora comparativamente entre los riesgos el impacto del riesgo sobre el alcance del proyecto frente a otros riesgos.
... A27: Un saludo.

Sheet PROBABILIDAD
B2: ESTIMACIÓN DE LA PROBABILIDAD DE OCURRENCIA DE LOS RIESGOS DEL PROYECTO
B3: ESTIMACIÓN DE LA PROBABILIDAD DE LOS RIESGOS DEL PROYECTO | C3: GRUPO | D3: SUBGRUPO | E3: RIESGO | F3: DESCRIPCIÓN | G3: PROBABILIDAD | X3: ESCALA DE PROBABILIDAD
C4: 1.- RIESGOS POLÍTICOS | D4: 1.1.- Macroeconómicos | E4: 1.1.1.- Nivel de estabilidad política | F4: Estabilidad del gobierno. | G4: 3 | X4: MUY ALTA
E5: 1.1.2.- Cambio en la política energética | F5: Riesgo asociado con los cambios en la política energética introducidos por las administraciones públicas. | G5: 2 | X5: ALTA
D6: 1.2- Licencias urbanísticas | E6: 1.2.1.- Aprobación del Ayuntamiento | F6: Riesgo político entendido como el nivel de interés del Ayuntamiento en el proyecto. La aprobación del proyecto tiene más riesgo si el nivel de interés es bajo. | G6: 5 | X6: MEDIA
E7: 1.2.2.- Obtención de la licencia de obras | F7: Riesgo asociado con el interés del Gobierno Municipal en conceder la licencia, ya que el Gobierno municipal puede considerar el proyecto de un nivel de prioridad más alto o más bajo. | G7: 4 | X7: BAJA
C8: GRUPO | D8: SUBGRUPO | E8: RIESGO | F8: DESCRIPCIÓN | G8: PROBABILIDAD | X8: MUY BAJA
C9: 2.- RIESGOS TÉCNICOS | D9: 2.1.- Ubicación de la planta | E9: 2.1.1.- Adecuación tecnológica al cambio climático | F9: Las actividades humanas pueden causar cambios climáticos. Esto genera una incertidumbre sobre la tecnología más conveniente a usar en el proyecto para asegurar un óptimo rendimiento durante toda su vida útil. | G9: 3
E10: 2.1.2.- Valoración de los riesgos de tormenta e inundación | F10: Riesgos de tormenta e inundación en el área donde se va a construir la planta fotovoltaica. | G10: 4
E11: 2.1.3.- Valoración de las horas efectivas de radiación de solar | F11: Hay siempre un índice de error en las estimaciones de radiación solar, que añade incertidumbre al proyecto. | G11: 5
E12: 2.1.4.- Terraplenes. | F12: Riesgo de mayores o menores problemas técnicos relacionados con la nivelación del terreno. | G12: 5
E13: 2.1.5.- Problemas geotécnicos del terreno | F13: Riesgo asociado a los problemas geotécnicos del terreno. | G13: 5
D14: 2.2.- Tecnología Fotovoltaica | E14: 2.2.1.- Nivel de obsolescencia de la tecnología fotovoltaica seleccionada. | F14: Nivel de obsolescencia de las tecnologías fotovoltaicas, en función del grado de innovación del sector. | G14: 3
E15: 2.2.2.- Elección del panel fotovoltaico | F15: La inadecuada elección de los paneles solares fotovoltaicos puede generar grandes pérdidas. | G15: 3
E16: 2.2.3.- Elección del inversor de corriente | F16: Riesgo asociado con la elección del inversor de corriente. | G16: 5
E17: 2.2.4.- Elección de la estructura soporte de los paneles fotovoltaicos | F17: El diseño y elección correcta del material de la estructura soporte de los paneles solares afectan a la durabilidad de la instalación y los costes de mantenimiento a lo largo de la vida útil de la instalación. | G17: 5
E18: 2.2.5.- Conexión con la red eléctrica | F18: La conexión a la red eléctrica requiere de sistemas de control técnicos complejos. | G18: 4
E19: 2.2.6.- Posibilidad de existencia de sistema de generación de energía alternativos | F19: Riesgo asociado con el desarrollo de nuevos sistemas de generación de energía en la zona donde se ubica el proyecto, los cuales pueden producir un rechazo a la energía solar fotovoltaica por parte del entorno social y administrativo. | G19: 5
C20: GRUPO | D20: SUBGRUPO | E20: RIESGO | F20: DESCRIPCIÓN | G20: PROBABILIDAD
C21: 3.- RIESGOS ECONÓMICOS | D21: 3.1.- Explotación de la planta | E21: 3.1.1.- Costes de operación de la planta | F21: Riesgo de variación de los costes de operación de la planta. | G21: 3
E22: 3.1.2.- Costes de mantenimiento correctivo | F22: Riesgo de variación de los costes de mantenimiento correctivo de la planta. | G22: 3
E23: 3.1.3.- Costes de mantenimiento preventivo | F23: Riesgo de variación de los costes de mantenimiento preventivo. | G23: 3
E24: 3.1.4.- Pérdidas de rendimiento | F24: Riesgo de un inadecuado cálculo de pérdidas de rendimiento de la planta fotovoltaica, lo que puede reducir la rentabilidad de la planta. | G24: 3
D25: 3.2.- Ubicación de la planta | E25: 3.2.1.- Estimación de ingresos basada en las horas efectivas de radiación solar | F25: Evaluación del posible error en la estimación de las horas solares de radiación efectiva. | G25: 4
E26: 3.2.2.- Estimación de ingresos debida al cambio climático | F26: El cambio climático puede afectar significativamente en la estimación de la rentabilidad de la planta fotovoltaica. | G26: 4
E27: 3.2.3.- Recursos para trabajos de terraplenado | F27: Riesgos de sobrecoste asociado a los trabajos para nivelación del terreno. | G27: 5
E28: 3.2.4.- Trabajos de prevención de inundaciones | F28: Sobrecostes debidos a los problemas asociados con el riesgo de inundaciones. | G28: 5
E29: 3.2.5.- Solución a problemas geotécnicos | F29: Riesgo de sobrecostes debidos a problemas de naturaleza geotécnica. | G29: 5
D30: 3.3.- Permisos para la puesta en marcha | E30: 3.3.1.- Costes de conexión a la red eléctrica | F30: El acuerdo con la compañía eléctrica implica ciertos costes que pueden variar dependiendo de las características de la red eléctrica en la que se realiza la conexión. | G30: 4
E31: 3.3.2.- Costes asociados a los acuerdos con los propietarios de los terrenos | F31: Evaluación de la buena voluntad de los propietarios de los terrenos para firmar los acuerdos con el promotor. | G31: 4
E32: 3.3.3.- Posibilidad de construcción de la infraestructura de conexión con la red eléctrica | F32: El punto de conexión con la red de transporte es responsabilidad de la Compañía Eléctrica. Sin embargo, en ocasiones puede obtarse por la construcción por parte del promotor y abaratar costes. | G32: 5
E33: 3.3.4.- Riesgos económicos relacionados con la obtención de la licencia de obras | F33: Riesgo asociado con los posibles requisitos del Ayuntamiento para obtener la licencia de obras. | G33: 3
D34: 3.4.- Macroeconómicos | E34: 3.4.1.- Obtención de la financiación bancaria | F34: Riesgo relacionado con la obtención de la financiación del banco para el proyecto. | G34: 3
E35: 3.4.2.- Cambios en la demanda de potencia | F35: Los cambios en la demanda de energía puede afectar a las estimaciones de rentabilidad de la planta. | G35: 5
E36: 3.4.3.- Cambios en el precio del dinero | F36: Influencia de la tasa de inflación en el cash-flow del proyecto durante la vida util del proyecto. | G36: 3
E37: 3.4.4.- Cambios en el precio de la energía | F37: Evaluación del riesgo de variación de los precios de la energía a lo largo de la vida útil del proyecto. | G37: 3
C38: GRUPO | D38: SUBGRUPO | E38: RIESGO | F38: DESCRIPCIÓN | G38: PROBABILIDAD
C39: 4.- RIESGOS POR RETRASOS | D39: 4.1.- Conexión con la red eléctrica | E39: 4.1.1.- Retrasos en la construcción de la infraestrutura de conexión con la red eléctrica | F39: Riesgo de retrasos en la construcción de la infraestructura de conexión con la red eléctrica. | G39: 3
E40: 4.1.2.- Retrasos en la obtención de la Autorización Administrativa para la construccíon de la infraestructura de conexión | F40: Riesgo de retrasos a la hora de obtener la Autorización Administrativa de la infraestructura de conexión con la red eléctrica. | G40: 3
E41: 4.1.3.- Retrasos en la obtención del Acta de Puesta en Marcha de la instalación fotovoltaica | F41: Evaluación del riesgo de retrasos en la obtención del Acta de Puesta en marcha de la planta. | G41: 3
...

Sheet RiskSerializationData
A1: 9 | B1: 0
A2: 0
A3: =#REF! -> #REF! | B3: TRUE | C3: 0 | D3: 1 | E3: GF1_rK0qDwEADAD5AAwjACYAOwBsAIAAgQCNAJkA0wD1AO8AKgD//wAAAAAAAQQAAAAAB0dlbmVyYWwAAAABK0UxIC8gMS4xLjEuLSBOaXZlbCBkZSBlc3RhYmlsaWRhZCBwb2zDrXRpY2EBAAEBEAACAAEKU3RhdGlzdGljcwMBAQD/AQEBAQEAAQEBAAIAAQEBAQEAAQEBAAIAAZ0AAjIAK0UxIC8gMS4xLjEuLSBOaXZlbCBkZSBlc3RhYmlsaWRhZCBwb2zDrXRpY2EAAC8BAgACANsA5QABAQIBmpmZmZmZqT8AAGZmZmZmZu4/AAAFAAEBAQABAQEA | F3: 1 | G3: 0 | H3: 0 | J3: >75% | K3: <25% | L3: >90% | AG3: =#REF! -> #REF! | AH3: 267 | AI3: 1 | AJ3: FALSE | AK3: TRUE | AL3: 0 | AM3: FALSE | AN3: =_ -> #NAME?
A4: =#REF! -> #REF! | B4: TRUE | C4: 0 | D4: 1 | E4: GF1_rK0qDwEADAC/AAwjACYAOwBPAGMAZABwAHwAmQC7ALUAKgD//wAAAAAAAQQAAAAAB0dlbmVyYWwAAAABDlJEMS4xLjEgLyBFQzE2AQABARAAAgABClN0YXRpc3RpY3MDAQEA/wEBAQEBAAEBAQACAAEBAQEBAAEBAQACAAGAAAIVAA5SRDEuMS4xIC8gRUMxNgAALwECAAIAoQCrAAEBAgGamZmZmZmpPwAAZmZmZmZm7j8AAAUAAQEBAAEBAQA= | F4: 1 | G4: 0 | H4: 0 | J4: >75% | K4: <25% | L4: >90% | AG4: =#REF! -> #REF! | AH4: 272 | AI4: 1 | AJ4: FALSE | AK4: TRUE | AL4: 0 | AM4: FALSE | AN4: =_ -> #NAME?
A5: =#REF! -> #REF! | B5: TRUE | C5: 0 | D5: 1 | E5: GF1_rK0qDwEADAD7AAwjACYAOwBtAIEAggCOAJoA1QD3APEAKgD//wAAAAAAAQQAAAAAB0dlbmVyYWwAAAABLDEuMS4xLi0gTml2ZWwgZGUgZXN0YWJpbGlkYWQgcG9sw610aWNhIC8gT1JGAQABARAAAgABClN0YXRpc3RpY3MDAQEA/wEBAQEBAAEBAQACAAEBAQEBAAEBAQACAAGeAAIzACwxLjEuMS4tIE5pdmVsIGRlIGVzdGFiaWxpZGFkIHBvbMOtdGljYSAvIE9SRgAALwECAAIA3QDnAAEBAgGamZmZmZmpPwAAZmZmZmZm7j8AAAUAAQEBAAEBAQA= | F5: 1 | G5: 0 | H5: 0 | J5: >75% | K5: <25% | L5: >90% | AG5: =#REF! -> #REF! | AH5: 900 | AI5: 1 | AJ5: FALSE | AK5: TRUE | AL5: 0 | AM5: FALSE | AN5: =_ -> #NAME?
A6: =#REF! -> #REF! | B6: TRUE | C6: 0 | D6: 1 | E6: GF1_rK0qDwEADAADAQwjACYAOwBxAIUAhgCSAJ4A3QD/APkAKgD//wAAAAAAAQQAAAAAB0dlbmVyYWwAAAABMDEuMS4xLi0gTml2ZWwgZGUgZXN0YWJpbGlkYWQgcG9sw610aWNhIC8gUkFOS0lORwEAAQEQAAIAAQpTdGF0aXN0aWNzAwEBAP8BAQEBAQABAQEAAgABAQEBAQABAQEAAgABogACNwAwMS4xLjEuLSBOaXZlbCBkZSBlc3RhYmlsaWRhZCBwb2zDrXRpY2EgLyBSQU5LSU5HAAAvAQIAAgDlAO8AAQECAZqZmZmZmak/AABmZmZmZmbuPwAABQABAQEAAQEBAA== | F6: 1 | G6: 0 | H6: 0 | J6: >75% | K6: <25% | L6: >90% | AG6: =#REF! -> #REF! | AH6: 901 | AI6: 1 | AJ6: FALSE | AK6: TRUE | AL6: 0 | AM6: FALSE | AN6: =_ -> #NAME?
A7: =#REF! -> #REF! | B7: TRUE | C7: 0 | D7: 1 | E7: GF1_rK0qDwEADADrAAwjACYAOwBlAHkAegCGAJIAxQDnAOEAKgD//wAAAAAAAQQAAAAAB0dlbmVyYWwAAAABJDYuMi4yLi0gQWNlcHRhY2nDs24gc29jaWFsIC8gUkFOS0lORwEAAQEQAAIAAQpTdGF0aXN0aWNzAwEBAP8BAQEBAQABAQEAAgABAQEBAQABAQEAAgABlgACKwAkNi4yLjIuLSBBY2VwdGFjacOzbiBzb2NpYWwgLyBSQU5LSU5HAAAvAQIAAgDNANcAAQECAZqZmZmZmak/AABmZmZmZmbuPwAABQABAQEAAQEBAA== | F7: 1 | G7: 0 | H7: 0 | J7: >75% | K7: <25% | L7: >90% | AG7: =#REF! -> #REF! | AH7: 1009 | AI7: 1 | AJ7: FALSE | AK7: TRUE | AL7: 0 | AM7: FALSE | AN7: =_ -> #NAME?
A8: =PROBABILIDAD!$K$4 -> 0 | B8: FALSE | C8: 1 | D8: 1 | E8: GF1_rK0qDwEADADwAAwjACYAOwBqAH4AfwCLAJcAygDsAOYAKgD//wAAAAAAAQQAAAAAB0dlbmVyYWwAAAABB0NSSVRJQ08BIkNvbXBhcmFjacOzbiBjb24gVHJpYW5nKDAsODswLDk7MSkBARAAAgABClN0YXRpc3RpY3MDAQEA/wEBAQEBAAEBAQACAAEBAQEBAAEBAQACAAKeAAKwAAAOAAdDUklUSUNPAAAvAQIAAgAYABFUcmlhbmcoMCw4OzAsOTsxKQEBJQECANIA3AABAQIBmpmZmZmZqT8AAGZmZmZmZu4/AAAFAAEBAQABAQEA | F8: 2 | G8: 0 | H8: 0 | AG8: =PROBABILIDAD!$K$4 -> 0 | AH8: 1 | AI8: 1 | AJ8: FALSE | AK8: FALSE | AL8: 1 | AM8: FALSE | AN8: =_ -> #NAME? | AO8: =PROBABILIDAD!$K$4 -> 0 | AP8: 1 | AQ8: 1 | AR8: TRUE | AS8: FALSE | AT8: 1 | AU8: TRUE | AV8: =_ -> #NAME?
A9: =PROBABILIDAD!$N$4 -> 0 | B9: FALSE | C9: 1 | D9: 1 | E9: GF1_rK0qDwEADAAPAQwjACYAOwBnAHsAfACIAJQA6QALAQUBKgD//wAAAAAAAQQAAAAAB0dlbmVyYWwAAAABBEFMVEEBIkNvbXBhcmFjacOzbiBjb24gVHJpYW5nKDAsNzswLDk7MSkBARAAAgABClN0YXRpc3RpY3MDAQEA/wEBAQEBAAEBAQACAAEBAQEBAAEBAQACAAShAAKwAADKAALaAAILAARBTFRBAAAvAQIAAgAYABFUcmlhbmcoMCw3OzAsOTsxKQEBJQECAAwABU1FRElBAQJPAQIAAgALAARCQUpBAQOMAQIAAgDxAPsAAQECAZqZmZmZmak/AABmZmZmZmbuPwAABQABAQEAAQEBAA== | F9: 4 | G9: 0 | H9: 0 | AG9: =PROBABILIDAD!$N$4 -> 0 | AH9: 2 | AI9: 1 | AJ9: FALSE | AK9: FALSE | AL9: 1 | AM9: FALSE | AN9: =_ -> #NAME? | AO9: =PROBABILIDAD!$N$4 -> 0 | AP9: 2 | AQ9: 1 | AR9: TRUE | AS9: FALSE | AT9: 1 | AU9: TRUE | AV9: =_ -> #NAME? | AW9: =PROBABILIDAD!$N$5 -> 0 | AX9: 4 | AY9: 1 | AZ9: FALSE | BA9: FALSE | BB9: 1 | BC9: FALSE | BD9: =_ -> #NAME? | BE9: =PROBABILIDAD!$N$6 -> 0 | BF9: 6 | BG9: 1 | BH9: FALSE | BI9: FALSE | BJ9: 1 | BK9: FALSE | BL9: =_ -> #NAME?
A10: =PROBABILIDAD!$K$5 -> 0 | B10: FALSE | C10: 1 | D10: 1 | E10: GF1_rK0qDwEADABMAQwjACYAOwBrAH8AgACMAJgAJgFIAUIBKgD//wAAAAAAAQQAAAAAB0dlbmVyYWwAAAABBVNFUklPASVDb21wYXJhY2nDs24gY29uIFRyaWFuZygwLDY7MCw3NTswLDkpAQEQAAIAAQpTdGF0aXN0aWNzAwEBAP8BAQEBAQABAQEAAgABAQEBAQABAQEAAgAGqwACuwAA2AAC6gAC/QACDQECDAAFU0VSSU8AAC8BAgACABsAFFRyaWFuZygwLDY7MCw3NTswLDkpAQElAQIADgAHQ1JJVElDTwECTwECAAIADwAITU9ERVJBRE8BA4wBAgACAAwABU1FTk9SAQRMAQIAAgAVAA5JTlNJR05JRklDQU5URQEFOQECAAIALgE4AQEBAgGamZmZmZmpPwAAZmZmZmZm7j8AAAUAAQEBAAEBAQA= | F10: 6 | G10: 0 | H10: 0 | AG10: =PROBABILIDAD!$K$5 -> 0 | AH10: 3 | AI10: 1 | AJ10: FALSE | AK10: FALSE | AL10: 1 | AM10: FALSE | AN10: =_ -> #NAME? | AO10: =PROBABILIDAD!$K$5 -> 0 | AP10: 3 | AQ10: 1 | AR10: TRUE | AS10: FALSE | AT10: 1 | AU10: TRUE | AV10: =_ -> #NAME? | AW10: =PROBABILIDAD!$K$4 -> 0 | AX10: 1 | AY10: 1 | AZ10: FALSE | BA10: FALSE | BB10: 1 | BC10: FALSE | BD10: =_ -> #NAME? | BE10: =PROBABILIDAD!$K$6 -> 0 | BF10: 5 | BG10: 1 | BH10: FALSE | BI10: FALSE | BJ10: 1 | BK10: FALSE | BL10: =_ -> #NAME? | BM10: =PROBABILIDAD!$K$7 -> 0 | BN10: 7 | BO10: 1 | BP10: FALSE | BQ10: FALSE | BR10: 1 | BS10: FALSE | BT10: =_ -> #NAME? | BU10: =PROBABILIDAD!$K$8 -> 0 | BV10: 8 | BW10: 1 | BX10: FALSE | BY10: FALSE | BZ10: 1 | CA10: FALSE | CB10: =_ -> #NAME?
A11: =PROBABILIDAD!#REF! -> #REF! | B11: FALSE | C11: 1 | D11: 1 | E11: GF1_rK0qDwEADACmAQwjACYAOwB3AIsAjACYAKQAgAGiAZwBKgD//wAAAAAAAQQAAAAAB0dlbmVyYWwAAAABFDYuMi4tIEltcGFjdG8gc29jaWFsASJDb21wYXJhY2nDs24gY29uIFRyaWFuZygwOzA7MCwxMjUpAQEQAAIAAQpTdGF0aXN0aWNzAwEBAP8BAQEBAQABAQEAAgABAQEBAQABAQEAAgAKwwAC4gAA/AACIQECNwECRAECUAECXAECaAECdAECGwAUNi4yLi0gSW1wYWN0byBzb2NpYWwAAC8BAgACABgAEVRyaWFuZygwOzA7MCwxMjUpAQElAQIAIQAaNi4yLjIuLSBBY2VwdGFjacOzbiBzb2NpYWwBAk8BAgACABIAC0RFU0NSSVBDSU9OAQOMAQIAAgAJAAJNSQEETAECAAIACAABMAEFOQECAAIACAABMQEGTgECAAIACAABMgEHIwECAAIACAABMwEIKQECAAIACAABNAEJYAECAAIAiAGSAQEBAgGamZmZmZmpPwAAZmZmZmZm7j8AAAUAAQEBAAEBAQA= | F11: 10 | G11: 0 | H11: 0 | AG11: =PROBABILIDAD!#REF! -> #REF! | AH11: 9 | AI11: 1 | AJ11: FALSE | AK11: FALSE | AL11: 1 | AM11: FALSE | AN11: =_ -> #NAME? | AO11: =PROBABILIDAD!#REF! -> #REF! | AP11: 9 | AQ11: 1 | AR11: TRUE | AS11: FALSE | AT11: 1 | AU11: TRUE | AV11: =_ -> #NAME? | AW11: =PROBABILIDAD!#REF! -> #REF! | AX11: 10 | AY11: 1 | AZ11: FALSE | BA11: FALSE | BB11: 1 | BC11: FALSE | BD11: =_ -> #NAME? | BE11: =PROBABILIDAD!#REF! -> #REF! | BF11: 11 | BG11: 1 | BH11: FALSE | BI11: FALSE | BJ11: 1 | BK11: FALSE | BL11: =_ -> #NAME? | BM11: =PROBABILIDAD!#REF! -> #REF! | BN11: 12 | BO11: 1 | BP11: FALSE | BQ11: FALSE | BR11: 1 | BS11: FALSE | BT11: =_ -> #NAME? | BU11: =PROBABILIDAD!#REF! -> #REF! | BV11: 13 | BW11: 1 | BX11: FALSE | BY11: FALSE | BZ11: 1 | CA11: FALSE | CB11: =_ -> #NAME? | CC11: =PROBABILIDAD!#REF! -> #REF! | CD11: 14 | CE11: 1 | CF11: FALSE | CG11: FALSE | CH11: 1 | CI11: FALSE | CJ11: =_ -> #NAME? | CK11: =PROBABILIDAD!#REF! -> #REF! | CL11: 15 | CM11: 1 | CN11: FALSE | CO11: FALSE | CP11: 1 | CQ11: FALSE | CR11: =_ -> #NAME? | CS11: =PROBABILIDAD!#REF! -> #REF! | CT11: 16 | CU11: 1 | CV11: FALSE | CW11: FALSE | CX11: 1 | CY11: FALSE | CZ11: =_ -> #NAME? | DA11: =PROBABILIDAD!#REF! -> #REF! | DB11: 17 | DC11: 1 | DD11: FALSE | DE11: FALSE | DF11: 1 | DG11: FALSE | DH11: =_ -> #NAME?
A12: 0
A13: FALSE | B13: 13440 | C13: 6215 | D13: 7050 | E13: 100
A14: FALSE | B14: 13440 | C14: 6215 | D14: 7050 | E14: 500
A15: FALSE | B15: 13440 | C15: 6215 | D15: 7050 | E15: 1000
A16: FALSE | B16: 13440 | C16: 6215 | D16: 7050 | E16: 1500
A17: FALSE | B17: 13440 | C17: 6215 | D17: 7050 | E17: 2000
A18: 0
A19: 0 | B19: FALSE | C19: FALSE | D19: 10 | E19: 0,95 | F19: 1

Sheet IMPACTO EN EL COSTE
B2: ESTIMACIÓN DEL IMPACTO DE LOS RIESGOS SOBRE EL COSTE DEL PROYECTO
B3: ESTIMACIÓN DE LA PROBABILIDAD DE LOS RIESGOS DEL PROYECTO | C3: GRUPO | D3: SUBGRUPO | E3: RIESGO | F3: DESCRIPCIÓN | G3: IMPACTO | X3: ESCALA DE IMPACTO
C4: 1.- RIESGOS POLÍTICOS | D4: 1.1.- Macroeconómicos | E4: 1.1.1.- Nivel de estabilidad política | F4: Estabilidad del gobierno. | G4: 5 | X4: CRÍTICO
E5: 1.1.2.- Cambio en la política energética | F5: Riesgo asociado con los cambios en la política energética introducidos por las administraciones públicas. | G5: 5 | X5: SERIO
D6: 1.2- Licencias urbanísticas | E6: 1.2.1.- Aprobación del Ayuntamiento | F6: Riesgo político entendido como el nivel de interés del Ayuntamiento en el proyecto. La aprobación del proyecto tiene más riesgo si el nivel de interés es bajo. | G6: 4 | X6: MODERADO
E7: 1.2.2.- Obtención de la licencia de obras | F7: Riesgo asociado con el interés del Gobierno Municipal en conceder la licencia, ya que el Gobierno municipal puede considerar el proyecto de un nivel de prioridad más alto o más bajo. | G7: 4 | X7: MENOR
C8: GRUPO | D8: SUBGRUPO | E8: RIESGO | F8: DESCRIPCIÓN | G8: IMPACTO | X8: INSIGNIFICANTE
C9: 2.- RIESGOS TÉCNICOS | D9: 2.1.- Ubicación de la planta | E9: 2.1.1.- Adecuación tecnológica al cambio climático | F9: Las actividades humanas pueden causar cambios climáticos. Esto genera una incertidumbre sobre la tecnología más conveniente a usar en el proyecto para asegurar un óptimo rendimiento durante toda su vida útil. | G9: 5
E10: 2.1.2.- Valoración de los riesgos de tormenta e inundación | F10: Riesgos de tormenta e inundación en el área donde se va a construir la planta fotovoltaica. | G10: 4
E11: 2.1.3.- Valoración de las horas efectivas de radiación de solar | F11: Hay siempre un índice de error en las estimaciones de radiación solar, que añade incertidumbre al proyecto. | G11: 5
E12: 2.1.4.- Terraplenes. | F12: Riesgo de mayores o menores problemas técnicos relacionados con la nivelación del terreno. | G12: 3
E13: 2.1.5.- Problemas geotécnicos del terreno | F13: Riesgo asociado a los problemas geotécnicos del terreno. | G13: 4
D14: 2.2.- Tecnología Fotovoltaica | E14: 2.2.1.- Nivel de obsolescencia de la tecnología fotovoltaica seleccionada. | F14: Nivel de obsolescencia de las tecnologías fotovoltaicas, en función del grado de innovación del sector. | G14: 5
E15: 2.2.2.- Elección del panel fotovoltaico | F15: La inadecuada elección de los paneles solares fotovoltaicos puede generar grandes pérdidas. | G15: 4
E16: 2.2.3.- Elección del inversor de corriente | F16: Riesgo asociado con la elección del inversor de corriente. | G16: 4
E17: 2.2.4.- Elección de la estructura soporte de los paneles fotovoltaicos | F17: El diseño y elección correcta del material de la estructura soporte de los paneles solares afectan a la durabilidad de la instalación y los costes de mantenimiento a lo largo de la vida útil de la instalación. | G17: 4
E18: 2.2.5.- Conexión con la red eléctrica | F18: La conexión a la red eléctrica requiere de sistemas de control técnicos complejos. | G18: 4
E19: 2.2.6.- Posibilidad de existencia de sistema de generación de energía alternativos | F19: Riesgo asociado con el desarrollo de nuevos sistemas de generación de energía en la zona donde se ubica el proyecto, los cuales pueden producir un rechazo a la energía solar fotovoltaica por parte del entorno social y administrativo. | G19: 5
C20: GRUPO | D20: SUBGRUPO | E20: RIESGO | F20: DESCRIPCIÓN | G20: IMPACTO
C21: 3.- RIESGOS ECONÓMICOS | D21: 3.1.- Explotación de la planta | E21: 3.1.1.- Costes de operación de la planta | F21: Riesgo de variación de los costes de operación de la planta. | G21: 5
E22: 3.1.2.- Costes de mantenimiento correctivo | F22: Riesgo de variación de los costes de mantenimiento correctivo de la planta. | G22: 5
E23: 3.1.3.- Costes de mantenimiento preventivo | F23: Riesgo de variación de los costes de mantenimiento preventivo. | G23: 5
E24: 3.1.4.- Pérdidas de rendimiento | F24: Riesgo de un inadecuado cálculo de pérdidas de rendimiento de la planta fotovoltaica, lo que puede reducir la rentabilidad de la planta. | G24: 5
D25: 3.2.- Ubicación de la planta | E25: 3.2.1.- Estimación de ingresos basada en las horas efectivas de radiación solar | F25: Evaluación del posible error en la estimación de las horas solares de radiación efectiva. | G25: 5
E26: 3.2.2.- Estimación de ingresos debida al cambio climático | F26: El cambio climático puede afectar significativamente en la estimación de la rentabilidad de la planta fotovoltaica. | G26: 5
E27: 3.2.3.- Recursos para trabajos de terraplenado | F27: Riesgos de sobrecoste asociado a los trabajos para nivelación del terreno. | G27: 3
E28: 3.2.4.- Trabajos de prevención de inundaciones | F28: Sobrecostes debidos a los problemas asociados con el riesgo de inundaciones. | G28: 4
E29: 3.2.5.- Solución a problemas geotécnicos | F29: Riesgo de sobrecostes debidos a problemas de naturaleza geotécnica. | G29: 3
D30: 3.3.- Permisos para la puesta en marcha | E30: 3.3.1.- Costes de conexión a la red eléctrica | F30: El acuerdo con la compañía eléctrica implica ciertos costes que pueden variar dependiendo de las características de la red eléctrica en la que se realiza la conexión. | G30: 4
E31: 3.3.2.- Costes asociados a los acuerdos con los propietarios de los terrenos | F31: Evaluación de la buena voluntad de los propietarios de los terrenos para firmar los acuerdos con el promotor. | G31: 4
E32: 3.3.3.- Posibilidad de construcción de la infraestructura de conexión con la red eléctrica | F32: El punto de conexión con la red de transporte es responsabilidad de la Compañía Eléctrica. Sin embargo, en ocasiones puede obtarse por la construcción por parte del promotor y abaratar costes. | G32: 4
E33: 3.3.4.- Riesgos económicos relacionados con la obtención de la licencia de obras | F33: Riesgo asociado con los posibles requisitos del Ayuntamiento para obtener la licencia de obras. | G33: 4
D34: 3.4.- Macroeconómicos | E34: 3.4.1.- Obtención de la financiación bancaria | F34: Riesgo relacionado con la obtención de la financiación del banco para el proyecto. | G34: 5
E35: 3.4.2.- Cambios en la demanda de potencia | F35: Los cambios en la demanda de energía puede afectar a las estimaciones de rentabilidad de la planta. | G35: 5
E36: 3.4.3.- Cambios en el precio del dinero | F36: Influencia de la tasa de inflación en el cash-flow del proyecto durante la vida util del proyecto. | G36: 5
E37: 3.4.4.- Cambios en el precio de la energía | F37: Evaluación del riesgo de variación de los precios de la energía a lo largo de la vida útil del proyecto. | G37: 5
C38: GRUPO | D38: SUBGRUPO | E38: RIESGO | F38: DESCRIPCIÓN | G38: IMPACTO
C39: 4.- RIESGOS POR RETRASOS | D39: 4.1.- Conexión con la red eléctrica | E39: 4.1.1.- Retrasos en la construcción de la infraestrutura de conexión con la red eléctrica | F39: Riesgo de retrasos en la construcción de la infraestructura de conexión con la red eléctrica. | G39: 4
E40: 4.1.2.- Retrasos en la obtención de la Autorización Administrativa para la construccíon de la infraestructura de conexión | F40: Riesgo de retrasos a la hora de obtener la Autorización Administrativa de la infraestructura de conexión con la red eléctrica. | G40: 5
E41: 4.1.3.- Retrasos en la obtención del Acta de Puesta en Marcha de la instalación fotovoltaica | F41: Evaluación del riesgo de retrasos en la obtención del Acta de Puesta en marcha de la planta. | G41: 3
...

Sheet IMPACTO EN EL PLAZO
B2: ESTIMACIÓN DEL IMPACTO DE LOS RIESGOS SOBRE EL PLAZO DEL PROYECTO
B3: ESTIMACIÓN DE LA PROBABILIDAD DE LOS RIESGOS DEL PROYECTO | C3: GRUPO | D3: SUBGRUPO | E3: RIESGO | F3: DESCRIPCIÓN | G3: IMPACTO | X3: ESCALA DE IMPACTO
C4: 1.- RIESGOS POLÍTICOS | D4: 1.1.- Macroeconómicos | E4: 1.1.1.- Nivel de estabilidad política | F4: Estabilidad del gobierno. | G4: 3 | X4: CRÍTICO
E5: 1.1.2.- Cambio en la política energética | F5: Riesgo asociado con los cambios en la política energética introducidos por las administraciones públicas. | G5: 3 | X5: SERIO
D6: 1.2- Licencias urbanísticas | E6: 1.2.1.- Aprobación del Ayuntamiento | F6: Riesgo político entendido como el nivel de interés del Ayuntamiento en el proyecto. La aprobación del proyecto tiene más riesgo si el nivel de interés es bajo. | G6: 2 | X6: MODERADO
E7: 1.2.2.- Obtención de la licencia de obras | F7: Riesgo asociado con el interés del Gobierno Municipal en conceder la licencia, ya que el Gobierno municipal puede considerar el proyecto de un nivel de prioridad más alto o más bajo. | G7: 2 | X7: MENOR
C8: GRUPO | D8: SUBGRUPO | E8: RIESGO | F8: DESCRIPCIÓN | G8: IMPACTO | X8: INSIGNIFICANTE
C9: 2.- RIESGOS TÉCNICOS | D9: 2.1.- Ubicación de la planta | E9: 2.1.1.- Adecuación tecnológica al cambio climático | F9: Las actividades humanas pueden causar cambios climáticos. Esto genera una incertidumbre sobre la tecnología más conveniente a usar en el proyecto para asegurar un óptimo rendimiento durante toda su vida útil. | G9: 4
E10: 2.1.2.- Valoración de los riesgos de tormenta e inundación | F10: Riesgos de tormenta e inundación en el área donde se va a construir la planta fotovoltaica. | G10: 5
E11: 2.1.3.- Valoración de las horas efectivas de radiación de solar | F11: Hay siempre un índice de error en las estimaciones de radiación solar, que añade incertidumbre al proyecto. | G11: 5
E12: 2.1.4.- Terraplenes. | F12: Riesgo de mayores o menores problemas técnicos relacionados con la nivelación del terreno. | G12: 4
E13: 2.1.5.- Problemas geotécnicos del terreno | F13: Riesgo asociado a los problemas geotécnicos del terreno. | G13: 4
D14: 2.2.- Tecnología Fotovoltaica | E14: 2.2.1.- Nivel de obsolescencia de la tecnología fotovoltaica seleccionada. | F14: Nivel de obsolescencia de las tecnologías fotovoltaicas, en función del grado de innovación del sector. | G14: 5
E15: 2.2.2.- Elección del panel fotovoltaico | F15: La inadecuada elección de los paneles solares fotovoltaicos puede generar grandes pérdidas. | G15: 5
E16: 2.2.3.- Elección del inversor de corriente | F16: Riesgo asociado con la elección del inversor de corriente. | G16: 5
E17: 2.2.4.- Elección de la estructura soporte de los paneles fotovoltaicos | F17: El diseño y elección correcta del material de la estructura soporte de los paneles solares afectan a la durabilidad de la instalación y los costes de mantenimiento a lo largo de la vida útil de la instalación. | G17: 5
E18: 2.2.5.- Conexión con la red eléctrica | F18: La conexión a la red eléctrica requiere de sistemas de control técnicos complejos. | G18: 1
E19: 2.2.6.- Posibilidad de existencia de sistema de generación de energía alternativos | F19: Riesgo asociado con el desarrollo de nuevos sistemas de generación de energía en la zona donde se ubica el proyecto, los cuales pueden producir un rechazo a la energía solar fotovoltaica por parte del entorno social y administrativo. | G19: 1
C20: GRUPO | D20: SUBGRUPO | E20: RIESGO | F20: DESCRIPCIÓN | G20: IMPACTO
C21: 3.- RIESGOS ECONÓMICOS | D21: 3.1.- Explotación de la planta | E21: 3.1.1.- Costes de operación de la planta | F21: Riesgo de variación de los costes de operación de la planta. | G21: 5
E22: 3.1.2.- Costes de mantenimiento correctivo | F22: Riesgo de variación de los costes de mantenimiento correctivo de la planta. | G22: 5
E23: 3.1.3.- Costes de mantenimiento preventivo | F23: Riesgo de variación de los costes de mantenimiento preventivo. | G23: 5
E24: 3.1.4.- Pérdidas de rendimiento | F24: Riesgo de un inadecuado cálculo de pérdidas de rendimiento de la planta fotovoltaica, lo que puede reducir la rentabilidad de la planta. | G24: 5
D25: 3.2.- Ubicación de la planta | E25: 3.2.1.- Estimación de ingresos basada en las horas efectivas de radiación solar | F25: Evaluación del posible error en la estimación de las horas solares de radiación efectiva. | G25: 5
E26: 3.2.2.- Estimación de ingresos debida al cambio climático | F26: El cambio climático puede afectar significativamente en la estimación de la rentabilidad de la planta fotovoltaica. | G26: 1
E27: 3.2.3.- Recursos para trabajos de terraplenado | F27: Riesgos de sobrecoste asociado a los trabajos para nivelación del terreno. | G27: 4
E28: 3.2.4.- Trabajos de prevención de inundaciones | F28: Sobrecostes debidos a los problemas asociados con el riesgo de inundaciones. | G28: 4
E29: 3.2.5.- Solución a problemas geotécnicos | F29: Riesgo de sobrecostes debidos a problemas de naturaleza geotécnica. | G29: 5
D30: 3.3.- Permisos para la puesta en marcha | E30: 3.3.1.- Costes de conexión a la red eléctrica | F30: El acuerdo con la compañía eléctrica implica ciertos costes que pueden variar dependiendo de las características de la red eléctrica en la que se realiza la conexión. | G30: 5
E31: 3.3.2.- Costes asociados a los acuerdos con los propietarios de los terrenos | F31: Evaluación de la buena voluntad de los propietarios de los terrenos para firmar los acuerdos con el promotor. | G31: 4
E32: 3.3.3.- Posibilidad de construcción de la infraestructura de conexión con la red eléctrica | F32: El punto de conexión con la red de transporte es responsabilidad de la Compañía Eléctrica. Sin embargo, en ocasiones puede obtarse por la construcción por parte del promotor y abaratar costes. | G32: 4
E33: 3.3.4.- Riesgos económicos relacionados con la obtención de la licencia de obras | F33: Riesgo asociado con los posibles requisitos del Ayuntamiento para obtener la licencia de obras. | G33: 4
D34: 3.4.- Macroeconómicos | E34: 3.4.1.- Obtención de la financiación bancaria | F34: Riesgo relacionado con la obtención de la financiación del banco para el proyecto. | G34: 3
E35: 3.4.2.- Cambios en la demanda de potencia | F35: Los cambios en la demanda de energía puede afectar a las estimaciones de rentabilidad de la planta. | G35: 5
E36: 3.4.3.- Cambios en el precio del dinero | F36: Influencia de la tasa de inflación en el cash-flow del proyecto durante la vida util del proyecto. | G36: 5
E37: 3.4.4.- Cambios en el precio de la energía | F37: Evaluación del riesgo de variación de los precios de la energía a lo largo de la vida útil del proyecto. | G37: 5
C38: GRUPO | D38: SUBGRUPO | E38: RIESGO | F38: DESCRIPCIÓN | G38: IMPACTO
C39: 4.- RIESGOS POR RETRASOS | D39: 4.1.- Conexión con la red eléctrica | E39: 4.1.1.- Retrasos en la construcción de la infraestrutura de conexión con la red eléctrica | F39: Riesgo de retrasos en la construcción de la infraestructura de conexión con la red eléctrica. | G39: 2
E40: 4.1.2.- Retrasos en la obtención de la Autorización Administrativa para la construccíon de la infraestructura de conexión | F40: Riesgo de retrasos a la hora de obtener la Autorización Administrativa de la infraestructura de conexión con la red eléctrica. | G40: 2
E41: 4.1.3.- Retrasos en la obtención del Acta de Puesta en Marcha de la instalación fotovoltaica | F41: Evaluación del riesgo de retrasos en la obtención del Acta de Puesta en marcha de la planta. | G41: 2
...

Sheet IMPACTO EN EL ALCANCE
B2: ESTIMACIÓN DEL IMPACTO DE LOS RIESGOS SOBRE EL ALCANCE DEL PROYECTO
B3: ESTIMACIÓN DE LA PROBABILIDAD DE LOS RIESGOS DEL PROYECTO | C3: GRUPO | D3: SUBGRUPO | E3: RIESGO | F3: DESCRIPCIÓN | G3: IMPACTO | X3: ESCALA DE IMPACTO
C4: 1.- RIESGOS POLÍTICOS | D4: 1.1.- Macroeconómicos | E4: 1.1.1.- Nivel de estabilidad política | F4: Estabilidad del gobierno. | G4: 4 | X4: CRÍTICO
E5: 1.1.2.- Cambio en la política energética | F5: Riesgo asociado con los cambios en la política energética introducidos por las administraciones públicas. | G5: 3 | X5: SERIO
D6: 1.2- Licencias urbanísticas | E6: 1.2.1.- Aprobación del Ayuntamiento | F6: Riesgo político entendido como el nivel de interés del Ayuntamiento en el proyecto. La aprobación del proyecto tiene más riesgo si el nivel de interés es bajo. | G6: 3 | X6: MODERADO
E7: 1.2.2.- Obtención de la licencia de obras | F7: Riesgo asociado con el interés del Gobierno Municipal en conceder la licencia, ya que el Gobierno municipal puede considerar el proyecto de un nivel de prioridad más alto o más bajo. | G7: 3 | X7: MENOR
C8: GRUPO | D8: SUBGRUPO | E8: RIESGO | F8: DESCRIPCIÓN | G8: IMPACTO | X8: INSIGNIFICANTE
C9: 2.- RIESGOS TÉCNICOS | D9: 2.1.- Ubicación de la planta | E9: 2.1.1.- Adecuación tecnológica al cambio climático | F9: Las actividades humanas pueden causar cambios climáticos. Esto genera una incertidumbre sobre la tecnología más conveniente a usar en el proyecto para asegurar un óptimo rendimiento durante toda su vida útil. | G9: 5
E10: 2.1.2.- Valoración de los riesgos de tormenta e inundación | F10: Riesgos de tormenta e inundación en el área donde se va a construir la planta fotovoltaica. | G10: 4
E11: 2.1.3.- Valoración de las horas efectivas de radiación de solar | F11: Hay siempre un índice de error en las estimaciones de radiación solar, que añade incertidumbre al proyecto. | G11: 5
E12: 2.1.4.- Terraplenes. | F12: Riesgo de mayores o menores problemas técnicos relacionados con la nivelación del terreno. | G12: 4
E13: 2.1.5.- Problemas geotécnicos del terreno | F13: Riesgo asociado a los problemas geotécnicos del terreno. | G13: 4
D14: 2.2.- Tecnología Fotovoltaica | E14: 2.2.1.- Nivel de obsolescencia de la tecnología fotovoltaica seleccionada. | F14: Nivel de obsolescencia de las tecnologías fotovoltaicas, en función del grado de innovación del sector. | G14: 5
E15: 2.2.2.- Elección del panel fotovoltaico | F15: La inadecuada elección de los paneles solares fotovoltaicos puede generar grandes pérdidas. | G15: 4
E16: 2.2.3.- Elección del inversor de corriente | F16: Riesgo asociado con la elección del inversor de corriente. | G16: 4
E17: 2.2.4.- Elección de la estructura soporte de los paneles fotovoltaicos | F17: El diseño y elección correcta del material de la estructura soporte de los paneles solares afectan a la durabilidad de la instalación y los costes de mantenimiento a lo largo de la vida útil de la instalación. | G17: 5
E18: 2.2.5.- Conexión con la red eléctrica | F18: La conexión a la red eléctrica requiere de sistemas de control técnicos complejos. | G18: 4
E19: 2.2.6.- Posibilidad de existencia de sistema de generación de energía alternativos | F19: Riesgo asociado con el desarrollo de nuevos sistemas de generación de energía en la zona donde se ubica el proyecto, los cuales pueden producir un rechazo a la energía solar fotovoltaica por parte del entorno social y administrativo. | G19: 5
C20: GRUPO | D20: SUBGRUPO | E20: RIESGO | F20: DESCRIPCIÓN | G20: IMPACTO
C21: 3.- RIESGOS ECONÓMICOS | D21: 3.1.- Explotación de la planta | E21: 3.1.1.- Costes de operación de la planta | F21: Riesgo de variación de los costes de operación de la planta. | G21: 5
E22: 3.1.2.- Costes de mantenimiento correctivo | F22: Riesgo de variación de los costes de mantenimiento correctivo de la planta. | G22: 5
E23: 3.1.3.- Costes de mantenimiento preventivo | F23: Riesgo de variación de los costes de mantenimiento preventivo. | G23: 5
E24: 3.1.4.- Pérdidas de rendimiento | F24: Riesgo de un inadecuado cálculo de pérdidas de rendimiento de la planta fotovoltaica, lo que puede reducir la rentabilidad de la planta. | G24: 5
D25: 3.2.- Ubicación de la planta | E25: 3.2.1.- Estimación de ingresos basada en las horas efectivas de radiación solar | F25: Evaluación del posible error en la estimación de las horas solares de radiación efectiva. | G25: 5
E26: 3.2.2.- Estimación de ingresos debida al cambio climático | F26: El cambio climático puede afectar significativamente en la estimación de la rentabilidad de la planta fotovoltaica. | G26: 5
E27: 3.2.3.- Recursos para trabajos de terraplenado | F27: Riesgos de sobrecoste asociado a los trabajos para nivelación del terreno. | G27: 5
E28: 3.2.4.- Trabajos de prevención de inundaciones | F28: Sobrecostes debidos a los problemas asociados con el riesgo de inundaciones. | G28: 5
E29: 3.2.5.- Solución a problemas geotécnicos | F29: Riesgo de sobrecostes debidos a problemas de naturaleza geotécnica. | G29: 5
D30: 3.3.- Permisos para la puesta en marcha | E30: 3.3.1.- Costes de conexión a la red eléctrica | F30: El acuerdo con la compañía eléctrica implica ciertos costes que pueden variar dependiendo de las características de la red eléctrica en la que se realiza la conexión. | G30: 3
E31: 3.3.2.- Costes asociados a los acuerdos con los propietarios de los terrenos | F31: Evaluación de la buena voluntad de los propietarios de los terrenos para firmar los acuerdos con el promotor. | G31: 3
E32: 3.3.3.- Posibilidad de construcción de la infraestructura de conexión con la red eléctrica | F32: El punto de conexión con la red de transporte es responsabilidad de la Compañía Eléctrica. Sin embargo, en ocasiones puede obtarse por la construcción por parte del promotor y abaratar costes. | G32: 4
E33: 3.3.4.- Riesgos económicos relacionados con la obtención de la licencia de obras | F33: Riesgo asociado con los posibles requisitos del Ayuntamiento para obtener la licencia de obras. | G33: 4
D34: 3.4.- Macroeconómicos | E34: 3.4.1.- Obtención de la financiación bancaria | F34: Riesgo relacionado con la obtención de la financiación del banco para el proyecto. | G34: 2
E35: 3.4.2.- Cambios en la demanda de potencia | F35: Los cambios en la demanda de energía puede afectar a las estimaciones de rentabilidad de la planta. | G35: 5
E36: 3.4.3.- Cambios en el precio del dinero | F36: Influencia de la tasa de inflación en el cash-flow del proyecto durante la vida util del proyecto. | G36: 5
E37: 3.4.4.- Cambios en el precio de la energía | F37: Evaluación del riesgo de variación de los precios de la energía a lo largo de la vida útil del proyecto. | G37: 5
C38: GRUPO | D38: SUBGRUPO | E38: RIESGO | F38: DESCRIPCIÓN | G38: IMPACTO
C39: 4.- RIESGOS POR RETRASOS | D39: 4.1.- Conexión con la red eléctrica | E39: 4.1.1.- Retrasos en la construcción de la infraestrutura de conexión con la red eléctrica | F39: Riesgo de retrasos en la construcción de la infraestructura de conexión con la red eléctrica. | G39: 3
E40: 4.1.2.- Retrasos en la obtención de la Autorización Administrativa para la construccíon de la infraestructura de conexión | F40: Riesgo de retrasos a la hora de obtener la Autorización Administrativa de la infraestructura de conexión con la red eléctrica. | G40: 3
E41: 4.1.3.- Retrasos en la obtención del Acta de Puesta en Marcha de la instalación fotovoltaica | F41: Evaluación del riesgo de retrasos en la obtención del Acta de Puesta en marcha de la planta. | G41: 3
...
