Workbook

Sheet PROJECT DESCRIPTION
A1: GENERAL PROJECT DESCRIPTION
A2: The photovoltaic solar plant will have a nominal power rating of 250 MW.
A4: The plant is located in a town in the Region of Murcia, containing between 10,000 and 100,000 inhabitants.
A6: Generated electric power will be transferred to the transportation network, owned by the electric company REE, S.A., through the 400 kV grid of an existing substation.
A8: Current land use: agricultural, primarily vineyards.
A10: Terrain: uneven with gentle slopes, with nearby scrubland areas marked by runoff.
A12: Environmental protection: unknown.
A14: Existence of other facilities in the area: several wind farms that evacuate at the same REE substation.
A18: Current status of the project: in the administrative processing phase.
A20: The total area used for implementation and construction of the photovoltaic solar plant is six million nine hundred and twenty one thousand nine hundred and twenty-two (6.921.922) square meters.
A22: The photovoltaic generator will consist of 180 groupings of 1.59 MW each, consisting of polycrystalline modules of renowned brands.
A24: For the installation of photovoltaic panels a monopole structure was selected, with the panels being placed at an incline of 24 degrees with respect to the horizontal plane, which is the optimal angle whan taking into account the shade and the weather conditions of the area.
... A40: The measurements of energy in the photovoltaic installation will be carried out at 30 kV, directly in the internal network high voltage network. This internal network is composed of 180 substations of 1,59 MVA. The CC energy produced will be transformed to AC and raised to high voltage. The transformation of the current will take place in 180 substations of 0.4 / 30 kV. The voltage will then be rasied from 30 kV to 132 kV and will be transported by a 12 km airline to the REE substation.

Sheet STEP-BY-STEP INSTRUCTIONS
A1: INSTRUCCIONES PARA SU CUMPLIMENTACIÓN
A4: En la primera pestaña se encuentra la descripción general del proyecto sobre el que tiene que emitir sus juicios de experto.
A6: A continuación tiene ya la encuesta en sí.
A8: En todas y cada una de las siguientes pestañas encuentra, de arriba hacia abajo:
A9: 1. La estructura organizativa de los riesgos, una estructura de tres niveles, con una descripción de cada uno de los riesgos y un combo en el que tiene que elegir su opinión en función de la pestaña en la que se encuentre:
A11: - Probabilidad: se valora la probabilidad de que el riesgo ocurra o se presente.
A12: - Impacto sobre el alcance del proyecto: se valora el impacto del riesgo sobre el alcance del proyecto, entendiendo alcance como el objetivo que se persigue con el proyecto y cuya consecución marcará la finalización con éxito del mismo.
A13: - Impacto sobre el coste: se valora el impacto de cada riesgo sobre el coste del proyecto.
A14: - Impacto sobre el plazo: se valora el impacto de cada riesgo sobre el plazo de desarrollo y ejecución del proyecto.
A16: 2. Una comparativa entre riesgos para cada grupo de los riesgos en los tres niveles de la estructura, con un combo en el que tiene que elegir su opinión comparativa de cada riesgo (fila) con el resto de riesgos que conforman el grupo (columna) en función de la pestaña en la que se encuentre:
A18: - Probabilidad: se valora comparativamente entre los riesgos la probabilidad de aparición de un riesgo frente a otro/s riesgos.
A19: - Impacto sobre el alcance del proyecto: se valora comparativamente entre los riesgos el impacto del riesgo sobre el alcance del proyecto frente a otros riesgos.
... A27: Un saludo.

Sheet PROBABILITY
B1: ESTIMATING THE PROBABILITY OF PROJECT RISK
B3: ESTIMATING THE PROBABILITY OF PROJECT RISK | C3: GROUP | D3: SUB-GROUP | E3: RISK | F3: DESCRIPTION | G3: PROBABILITY | Y3: PROBABILITY SCALE
C4: 1.- POLITICAL RISKS | D4: 1.1.- Macroeconomics | E4: 1.1.1.- Level of political stability | F4: Government stability | G4: 2 | Y4: VERY HIGH
E5: 1.1.2.- The change in energy policy | F5: Assessment of the risk associated with energy policy changes introduced by public administrations | G5: 1 | Y5: HIGH
D6: 1.2- Urban licenses | E6: 1.2.1.- Approval of the Local Body | F6: Political risk understood as the level of the interest in the project by the Town Mayor. Project approval is riskier if the tevel of interest is low. By contrast, projects of great interest are more likely to be approved. | G6: 3 | Y6: MEDIUM
E7: 1.2.2.- Obtainig the construction license | F7: Assessment of the associated risk with the interest of the City Council to grant the license. It is a political risk as the City Council may consider the project of a higher or lower priority. | G7: 3 | Y7: LOW
C8: GROUP | D8: SUB-GROUP | E8: RISK | F8: DESCRIPTION | G8: PROBABILITY | Y8: VERY LOW
C9: 2.- TECHNICAL RISKS | D9: 2.1.- Plant location | E9: 2.1.1.- Technological climate change adequacy | F9: Human activities may cause climate changes. This generates uncertainty when deciding the most suitable technology to use as the project should have a useful ife of at least 25 years, alongwhich significant climate changesmay occur. | G9: 3
E10: 2.1.2.- Flood and storm risks | F10: Assessment of flood and storm risks in the area where the PV power plant is to be built. | G10: 3
E11: 2.1.3.- Estimation of effective solar radiation | F11: There is always an error index in the estimates of solar radiation, which adds uncertainty to the project. The availability of historical statistical data of the area permits prioritizing among possible plant sites. | G11: 4
E12: 2.1.4.- Earthworks | F12: Risk of higher or lower technical problems associated with land levelling. | G12: 3
E13: 2.1.5.- Geotechnical study | F13: Assessment of the risk associated with the geotechnical problems. | G13: 3
D14: 2.2.- PV Technology | E14: 2.2.1.- New PV solar power systems | F14: Assessment of the risk in the development of new technologies. | G14: 3
E15: 2.2.2.- PV cell selection | F15: The inadequate selection of the solar panels may generate great losses. The type of solar panels will depend on the plant site. | G15: 3
E16: 2.2.3.- Inverters selection | F16: Assessment of the risk associated with the selection of the inverters. | G16: 3
E17: 2.2.4.- Selection of support pannel structure | F17: A good design and the correct choice of material of the support structure of solar panels can increase the durability of the installation and maintenance costs decrease throughout its life. | G17: 3
E18: 2.2.5.- Connection to the electric grid | F18: The connection to the electric grid requires accurate technical control systems. | G18: 3
E19: 2.2.6.- Alternative power generation systems | F19: Assessment of the risk associated with the development of new power generation systems in the site of the project, which may make public administrations reluctant to support PV. | G19: 3
C20: GROUP | D20: SUB-GROUP | E20: RISK | F20: DESCRIPTION | G20: PROBABILITY
C21: 3.- ECONOMIC RISKS | D21: 3.1.- Plant exploitation | E21: 3.1.1.- Plant operation cost | F21: Assessment of the risk of higher or lower operational costs. | G21: 4
E22: 3.1.2.- Corrective maintenance costs | F22: Assessment of the risk of higher or lower plant maintenance costs. | G22: 3
E23: 3.1.3.- Prevention of maintenance costs | F23: Assessment of the risk of higher or lower preventive maintenance costs. | G23: 4
E24: 3.1.4.- Performance losses | F24: Assessment of the risk of not adequately considering PV plant performance losses. This can reduce plant profitability. | G24: 3
D25: 3.2.- Plant location | E25: 3.2.1.- Errors in estimating the effective solar radiation energy | F25: Assessment of the possible errors in the estimates of effective solar radiation hours. A lack of consistency in the estimation of effective solar radiation hours will negatively affect PV plant profitability. | G25: 3
E26: 3.2.2.- Revenue estimation due to the climate change | F26: Climate change may significantly affect the estimates of PV plant profitability. | G26: 3
E27: 3.2.3.- Earthworks resources | F27: Risk of extra expenses associated with the corrective measures for land levelling. | G27: 3
E28: 3.2.4.- Flood prevention works | F28: Assessment of the risk of extra expenses due to problems associated with flood risks. | G28: 3
E29: 3.2.5.- Solution of geotechnical problems | F29: Assessment of the risk of extra expenses due to problems of geotechnical nature. | G29: 3
D30: 3.3.- Start-up permits | E30: 3.3.1.- Connection to the electric grid costs | F30: The agreement with the power supply company involves certain costs that may vary depending on the characteristics of the power connection system. | G30: 3
E31: 3.3.2.- Agreement costs with landowners | F31: Assessment of land owners willingness to sign an agreement with the land owner. | G31: 2
E32: 3.3.3.- Possibility of constructing the power connection infrastructure | F32: The connection point to the transport line is the Power Company’s responsibility. Usually the company fixes the connection point that best fits its interests. Therefore, the costs of constructing the power connection infrastruture must be estimated. | G32: 3
E33: 3.3.4.- Construction license | F33: Assessment of the risk associated with possible City Council requirements to obtain the construction license. | G33: 3
D34: 3.4.- Technology | E34: 3.4.1.- Costs due to the inadequate PV cell selection | F34: Evaluation of the costs associated with a bad choice of the photovoltaic panel. | G34: 3
E35: 3.4.2.- Costs due to inadequate inverter selection | F35: Evaluation of the costs associated with a bad choice of the photovoltaic inverter. | G35: 3
E36: 3.4.3.- Costs due to lack of consistency in the selection of support panels | F36: Evaluation of the costs associated with the repair and/or replacement of the support structure of the photovoltaic panels. | G36: 4
D37: 3.5.- Macroeconomics | E37: 3.5.1.- Bank financing | F37: Assessment of the risk for obtaining bank financing for the project. | G37: 2
E38: 3.5.2.- Changes in power demand | F38: Changes in power demand may affect the estimates of plant profitability. | G38: 2
E39: 3.5.3.- Inflation | F39: Influence of the inflation rate on the project cash-flow over the PV plant lifespan. | G39: 2
E40: 3.5.4.- Changes in energy prices | F40: Assessment of whether there is any risk of energy prices varying during the PV plant lifespan. | G40: 2
C41: GROUP | D41: SUB-GROUP | E41: RISK | F41: DESCRIPTION | G41: PROBABILITY
...

Sheet RiskSerializationData
A1: 9 | B1: 0
A2: 0
A3: =#REF! -> #REF! | B3: TRUE | C3: 0 | D3: 1 | E3: GF1_rK0qDwEADAD5AAwjACYAOwBsAIAAgQCNAJkA0wD1AO8AKgD//wAAAAAAAQQAAAAAB0dlbmVyYWwAAAABK0UxIC8gMS4xLjEuLSBOaXZlbCBkZSBlc3RhYmlsaWRhZCBwb2zDrXRpY2EBAAEBEAACAAEKU3RhdGlzdGljcwMBAQD/AQEBAQEAAQEBAAIAAQEBAQEAAQEBAAIAAZ0AAjIAK0UxIC8gMS4xLjEuLSBOaXZlbCBkZSBlc3RhYmlsaWRhZCBwb2zDrXRpY2EAAC8BAgACANsA5QABAQIBmpmZmZmZqT8AAGZmZmZmZu4/AAAFAAEBAQABAQEA | F3: 1 | G3: 0 | H3: 0 | J3: >75% | K3: <25% | L3: >90% | AG3: =#REF! -> #REF! | AH3: 267 | AI3: 1 | AJ3: FALSE | AK3: TRUE | AL3: 0 | AM3: FALSE | AN3: =_ -> #NAME?
A4: =#REF! -> #REF! | B4: TRUE | C4: 0 | D4: 1 | E4: GF1_rK0qDwEADAC/AAwjACYAOwBPAGMAZABwAHwAmQC7ALUAKgD//wAAAAAAAQQAAAAAB0dlbmVyYWwAAAABDlJEMS4xLjEgLyBFQzE2AQABARAAAgABClN0YXRpc3RpY3MDAQEA/wEBAQEBAAEBAQACAAEBAQEBAAEBAQACAAGAAAIVAA5SRDEuMS4xIC8gRUMxNgAALwECAAIAoQCrAAEBAgGamZmZmZmpPwAAZmZmZmZm7j8AAAUAAQEBAAEBAQA= | F4: 1 | G4: 0 | H4: 0 | J4: >75% | K4: <25% | L4: >90% | AG4: =#REF! -> #REF! | AH4: 272 | AI4: 1 | AJ4: FALSE | AK4: TRUE | AL4: 0 | AM4: FALSE | AN4: =_ -> #NAME?
A5: =#REF! -> #REF! | B5: TRUE | C5: 0 | D5: 1 | E5: GF1_rK0qDwEADAD7AAwjACYAOwBtAIEAggCOAJoA1QD3APEAKgD//wAAAAAAAQQAAAAAB0dlbmVyYWwAAAABLDEuMS4xLi0gTml2ZWwgZGUgZXN0YWJpbGlkYWQgcG9sw610aWNhIC8gT1JGAQABARAAAgABClN0YXRpc3RpY3MDAQEA/wEBAQEBAAEBAQACAAEBAQEBAAEBAQACAAGeAAIzACwxLjEuMS4tIE5pdmVsIGRlIGVzdGFiaWxpZGFkIHBvbMOtdGljYSAvIE9SRgAALwECAAIA3QDnAAEBAgGamZmZmZmpPwAAZmZmZmZm7j8AAAUAAQEBAAEBAQA= | F5: 1 | G5: 0 | H5: 0 | J5: >75% | K5: <25% | L5: >90% | AG5: =#REF! -> #REF! | AH5: 900 | AI5: 1 | AJ5: FALSE | AK5: TRUE | AL5: 0 | AM5: FALSE | AN5: =_ -> #NAME?
A6: =#REF! -> #REF! | B6: TRUE | C6: 0 | D6: 1 | E6: GF1_rK0qDwEADAADAQwjACYAOwBxAIUAhgCSAJ4A3QD/APkAKgD//wAAAAAAAQQAAAAAB0dlbmVyYWwAAAABMDEuMS4xLi0gTml2ZWwgZGUgZXN0YWJpbGlkYWQgcG9sw610aWNhIC8gUkFOS0lORwEAAQEQAAIAAQpTdGF0aXN0aWNzAwEBAP8BAQEBAQABAQEAAgABAQEBAQABAQEAAgABogACNwAwMS4xLjEuLSBOaXZlbCBkZSBlc3RhYmlsaWRhZCBwb2zDrXRpY2EgLyBSQU5LSU5HAAAvAQIAAgDlAO8AAQECAZqZmZmZmak/AABmZmZmZmbuPwAABQABAQEAAQEBAA== | F6: 1 | G6: 0 | H6: 0 | J6: >75% | K6: <25% | L6: >90% | AG6: =#REF! -> #REF! | AH6: 901 | AI6: 1 | AJ6: FALSE | AK6: TRUE | AL6: 0 | AM6: FALSE | AN6: =_ -> #NAME?
A7: =#REF! -> #REF! | B7: TRUE | C7: 0 | D7: 1 | E7: GF1_rK0qDwEADADrAAwjACYAOwBlAHkAegCGAJIAxQDnAOEAKgD//wAAAAAAAQQAAAAAB0dlbmVyYWwAAAABJDYuMi4yLi0gQWNlcHRhY2nDs24gc29jaWFsIC8gUkFOS0lORwEAAQEQAAIAAQpTdGF0aXN0aWNzAwEBAP8BAQEBAQABAQEAAgABAQEBAQABAQEAAgABlgACKwAkNi4yLjIuLSBBY2VwdGFjacOzbiBzb2NpYWwgLyBSQU5LSU5HAAAvAQIAAgDNANcAAQECAZqZmZmZmak/AABmZmZmZmbuPwAABQABAQEAAQEBAA== | F7: 1 | G7: 0 | H7: 0 | J7: >75% | K7: <25% | L7: >90% | AG7: =#REF! -> #REF! | AH7: 1009 | AI7: 1 | AJ7: FALSE | AK7: TRUE | AL7: 0 | AM7: FALSE | AN7: =_ -> #NAME?
A8: =PROBABILITY!$L$4 -> 0 | B8: FALSE | C8: 1 | D8: 1 | E8: GF1_rK0qDwEADADwAAwjACYAOwBqAH4AfwCLAJcAygDsAOYAKgD//wAAAAAAAQQAAAAAB0dlbmVyYWwAAAABB0NSSVRJQ08BIkNvbXBhcmFjacOzbiBjb24gVHJpYW5nKDAsODswLDk7MSkBARAAAgABClN0YXRpc3RpY3MDAQEA/wEBAQEBAAEBAQACAAEBAQEBAAEBAQACAAKeAAKwAAAOAAdDUklUSUNPAAAvAQIAAgAYABFUcmlhbmcoMCw4OzAsOTsxKQEBJQECANIA3AABAQIBmpmZmZmZqT8AAGZmZmZmZu4/AAAFAAEBAQABAQEA | F8: 2 | G8: 0 | H8: 0 | AG8: =PROBABILITY!$L$4 -> 0 | AH8: 1 | AI8: 1 | AJ8: FALSE | AK8: FALSE | AL8: 1 | AM8: FALSE | AN8: =_ -> #NAME? | AO8: =PROBABILITY!$L$4 -> 0 | AP8: 1 | AQ8: 1 | AR8: TRUE | AS8: FALSE | AT8: 1 | AU8: TRUE | AV8: =_ -> #NAME?
A9: =PROBABILITY!$O$4 -> 0 | B9: FALSE | C9: 1 | D9: 1 | E9: GF1_rK0qDwEADAAPAQwjACYAOwBnAHsAfACIAJQA6QALAQUBKgD//wAAAAAAAQQAAAAAB0dlbmVyYWwAAAABBEFMVEEBIkNvbXBhcmFjacOzbiBjb24gVHJpYW5nKDAsNzswLDk7MSkBARAAAgABClN0YXRpc3RpY3MDAQEA/wEBAQEBAAEBAQACAAEBAQEBAAEBAQACAAShAAKwAADKAALaAAILAARBTFRBAAAvAQIAAgAYABFUcmlhbmcoMCw3OzAsOTsxKQEBJQECAAwABU1FRElBAQJPAQIAAgALAARCQUpBAQOMAQIAAgDxAPsAAQECAZqZmZmZmak/AABmZmZmZmbuPwAABQABAQEAAQEBAA== | F9: 4 | G9: 0 | H9: 0 | AG9: =PROBABILITY!$O$4 -> 0 | AH9: 2 | AI9: 1 | AJ9: FALSE | AK9: FALSE | AL9: 1 | AM9: FALSE | AN9: =_ -> #NAME? | AO9: =PROBABILITY!$O$4 -> 0 | AP9: 2 | AQ9: 1 | AR9: TRUE | AS9: FALSE | AT9: 1 | AU9: TRUE | AV9: =_ -> #NAME? | AW9: =PROBABILITY!$O$5 -> 0 | AX9: 4 | AY9: 1 | AZ9: FALSE | BA9: FALSE | BB9: 1 | BC9: FALSE | BD9: =_ -> #NAME? | BE9: =PROBABILITY!$O$6 -> 0 | BF9: 6 | BG9: 1 | BH9: FALSE | BI9: FALSE | BJ9: 1 | BK9: FALSE | BL9: =_ -> #NAME?
A10: =PROBABILITY!$L$5 -> 0 | B10: FALSE | C10: 1 | D10: 1 | E10: GF1_rK0qDwEADABMAQwjACYAOwBrAH8AgACMAJgAJgFIAUIBKgD//wAAAAAAAQQAAAAAB0dlbmVyYWwAAAABBVNFUklPASVDb21wYXJhY2nDs24gY29uIFRyaWFuZygwLDY7MCw3NTswLDkpAQEQAAIAAQpTdGF0aXN0aWNzAwEBAP8BAQEBAQABAQEAAgABAQEBAQABAQEAAgAGqwACuwAA2AAC6gAC/QACDQECDAAFU0VSSU8AAC8BAgACABsAFFRyaWFuZygwLDY7MCw3NTswLDkpAQElAQIADgAHQ1JJVElDTwECTwECAAIADwAITU9ERVJBRE8BA4wBAgACAAwABU1FTk9SAQRMAQIAAgAVAA5JTlNJR05JRklDQU5URQEFOQECAAIALgE4AQEBAgGamZmZmZmpPwAAZmZmZmZm7j8AAAUAAQEBAAEBAQA= | F10: 6 | G10: 0 | H10: 0 | AG10: =PROBABILITY!$L$5 -> 0 | AH10: 3 | AI10: 1 | AJ10: FALSE | AK10: FALSE | AL10: 1 | AM10: FALSE | AN10: =_ -> #NAME? | AO10: =PROBABILITY!$L$5 -> 0 | AP10: 3 | AQ10: 1 | AR10: TRUE | AS10: FALSE | AT10: 1 | AU10: TRUE | AV10: =_ -> #NAME? | AW10: =PROBABILITY!$L$4 -> 0 | AX10: 1 | AY10: 1 | AZ10: FALSE | BA10: FALSE | BB10: 1 | BC10: FALSE | BD10: =_ -> #NAME? | BE10: =PROBABILITY!$L$6 -> 0 | BF10: 5 | BG10: 1 | BH10: FALSE | BI10: FALSE | BJ10: 1 | BK10: FALSE | BL10: =_ -> #NAME? | BM10: =PROBABILITY!$L$7 -> 0 | BN10: 7 | BO10: 1 | BP10: FALSE | BQ10: FALSE | BR10: 1 | BS10: FALSE | BT10: =_ -> #NAME? | BU10: =PROBABILITY!$L$8 -> 0 | BV10: 8 | BW10: 1 | BX10: FALSE | BY10: FALSE | BZ10: 1 | CA10: FALSE | CB10: =_ -> #NAME?
A11: =PROBABILITY!#REF! -> #REF! | B11: FALSE | C11: 1 | D11: 1 | E11: GF1_rK0qDwEADACmAQwjACYAOwB3AIsAjACYAKQAgAGiAZwBKgD//wAAAAAAAQQAAAAAB0dlbmVyYWwAAAABFDYuMi4tIEltcGFjdG8gc29jaWFsASJDb21wYXJhY2nDs24gY29uIFRyaWFuZygwOzA7MCwxMjUpAQEQAAIAAQpTdGF0aXN0aWNzAwEBAP8BAQEBAQABAQEAAgABAQEBAQABAQEAAgAKwwAC4gAA/AACIQECNwECRAECUAECXAECaAECdAECGwAUNi4yLi0gSW1wYWN0byBzb2NpYWwAAC8BAgACABgAEVRyaWFuZygwOzA7MCwxMjUpAQElAQIAIQAaNi4yLjIuLSBBY2VwdGFjacOzbiBzb2NpYWwBAk8BAgACABIAC0RFU0NSSVBDSU9OAQOMAQIAAgAJAAJNSQEETAECAAIACAABMAEFOQECAAIACAABMQEGTgECAAIACAABMgEHIwECAAIACAABMwEIKQECAAIACAABNAEJYAECAAIAiAGSAQEBAgGamZmZmZmpPwAAZmZmZmZm7j8AAAUAAQEBAAEBAQA= | F11: 10 | G11: 0 | H11: 0 | AG11: =PROBABILITY!#REF! -> #REF! | AH11: 9 | AI11: 1 | AJ11: FALSE | AK11: FALSE | AL11: 1 | AM11: FALSE | AN11: =_ -> #NAME? | AO11: =PROBABILITY!#REF! -> #REF! | AP11: 9 | AQ11: 1 | AR11: TRUE | AS11: FALSE | AT11: 1 | AU11: TRUE | AV11: =_ -> #NAME? | AW11: =PROBABILITY!#REF! -> #REF! | AX11: 10 | AY11: 1 | AZ11: FALSE | BA11: FALSE | BB11: 1 | BC11: FALSE | BD11: =_ -> #NAME? | BE11: =PROBABILITY!#REF! -> #REF! | BF11: 11 | BG11: 1 | BH11: FALSE | BI11: FALSE | BJ11: 1 | BK11: FALSE | BL11: =_ -> #NAME? | BM11: =PROBABILITY!#REF! -> #REF! | BN11: 12 | BO11: 1 | BP11: FALSE | BQ11: FALSE | BR11: 1 | BS11: FALSE | BT11: =_ -> #NAME? | BU11: =PROBABILITY!#REF! -> #REF! | BV11: 13 | BW11: 1 | BX11: FALSE | BY11: FALSE | BZ11: 1 | CA11: FALSE | CB11: =_ -> #NAME? | CC11: =PROBABILITY!#REF! -> #REF! | CD11: 14 | CE11: 1 | CF11: FALSE | CG11: FALSE | CH11: 1 | CI11: FALSE | CJ11: =_ -> #NAME? | CK11: =PROBABILITY!#REF! -> #REF! | CL11: 15 | CM11: 1 | CN11: FALSE | CO11: FALSE | CP11: 1 | CQ11: FALSE | CR11: =_ -> #NAME? | CS11: =PROBABILITY!#REF! -> #REF! | CT11: 16 | CU11: 1 | CV11: FALSE | CW11: FALSE | CX11: 1 | CY11: FALSE | CZ11: =_ -> #NAME? | DA11: =PROBABILITY!#REF! -> #REF! | DB11: 17 | DC11: 1 | DD11: FALSE | DE11: FALSE | DF11: 1 | DG11: FALSE | DH11: =_ -> #NAME?
A12: 0
A13: FALSE | B13: 13440 | C13: 6215 | D13: 7050 | E13: 100
A14: FALSE | B14: 13440 | C14: 6215 | D14: 7050 | E14: 500
A15: FALSE | B15: 13440 | C15: 6215 | D15: 7050 | E15: 1000
A16: FALSE | B16: 13440 | C16: 6215 | D16: 7050 | E16: 1500
A17: FALSE | B17: 13440 | C17: 6215 | D17: 7050 | E17: 2000
A18: 0
A19: 0 | B19: FALSE | C19: FALSE | D19: 10 | E19: 0,95 | F19: 1

Sheet SCOPE IMPACT
B1: ESTIMATING THE PROJECT RISKS IMPACT ON THE SCOPE
B3: ESTIMATING THE PROJECT RISKS IMPACT ON THE SCOPE | C3: GROUP | D3: SUB-GROUP | E3: RISK | F3: DESCRIPTION | G3: IMPACT | Y3: IMPACT SCALE
C4: 1.- POLITICAL RISKS | D4: 1.1.- Macroeconomics | E4: 1.1.1.- Level of political stability | F4: Government stability | G4: 2 | Y4: CRITICAL
E5: 1.1.2.- The change in energy policy | F5: Assessment of the risk associated with energy policy changes introduced by public administrations | G5: 1 | Y5: SERIOUS
D6: 1.2- Urban licenses | E6: 1.2.1.- Approval of the Local Body | F6: Political risk understood as the level of the interest in the project by the Town Mayor. Project approval is riskier if the tevel of interest is low. By contrast, projects of great interest are more likely to be approved. | G6: 3 | Y6: MODERATE
E7: 1.2.2.- Obtainig the construction license | F7: Assessment of the associated risk with the interest of the City Council to grant the license. It is a political risk as the City Council may consider the project of a higher or lower priority. | G7: 2 | Y7: MINOR
C8: GROUP | D8: SUB-GROUP | E8: RISK | F8: DESCRIPTION | G8: IMPACT | Y8: NEGLIGIBLE
C9: 2.- TECHNICAL RISKS | D9: 2.1.- Plant location | E9: 2.1.1.- Technological climate change adequacy | F9: Human activities may cause climate changes. This generates uncertainty when deciding the most suitable technology to use as the project should have a useful ife of at least 25 years, alongwhich significant climate changesmay occur. | G9: 3
E10: 2.1.2.- Flood and storm risks | F10: Assessment of flood and storm risks in the area where the PV power plant is to be built. | G10: 3
E11: 2.1.3.- Estimation of effective solar radiation | F11: There is always an error index in the estimates of solar radiation, which adds uncertainty to the project. The availability of historical statistical data of the area permits prioritizing among possible plant sites. | G11: 1
E12: 2.1.4.- Earthworks | F12: Risk of higher or lower technical problems associated with land levelling. | G12: 3
E13: 2.1.5.- Geotechnical study | F13: Assessment of the risk associated with the geotechnical problems. | G13: 2
D14: 2.2.- PV Technology | E14: 2.2.1.- New PV solar power systems | F14: Assessment of the risk in the development of new technologies. | G14: 3
E15: 2.2.2.- PV cell selection | F15: The inadequate selection of the solar panels may generate great losses. The type of solar panels will depend on the plant site. | G15: 1
E16: 2.2.3.- Inverters selection | F16: Assessment of the risk associated with the selection of the inverters. | G16: 1
E17: 2.2.4.- Selection of support pannel structure | F17: A good design and the correct choice of material of the support structure of solar panels can increase the durability of the installation and maintenance costs decrease throughout its life. | G17: 3
E18: 2.2.5.- Connection to the electric grid | F18: The connection to the electric grid requires accurate technical control systems. | G18: 3
E19: 2.2.6.- Alternative power generation systems | F19: Assessment of the risk associated with the development of new power generation systems in the site of the project, which may make public administrations reluctant to support PV. | G19: 3
C20: GROUP | D20: SUB-GROUP | E20: RISK | F20: DESCRIPTION | G20: IMPACT
C21: 3.- ECONOMIC RISKS | D21: 3.1.- Plant exploitation | E21: 3.1.1.- Plant operation cost | F21: Assessment of the risk of higher or lower operational costs. | G21: 3
E22: 3.1.2.- Corrective maintenance costs | F22: Assessment of the risk of higher or lower plant maintenance costs. | G22: 2
E23: 3.1.3.- Prevention of maintenance costs | F23: Assessment of the risk of higher or lower preventive maintenance costs. | G23: 2
E24: 3.1.4.- Performance losses | F24: Assessment of the risk of not adequately considering PV plant performance losses. This can reduce plant profitability. | G24: 2
D25: 3.2.- Plant location | E25: 3.2.1.- Errors in estimating the effective solar radiation energy | F25: Assessment of the possible errors in the estimates of effective solar radiation hours. A lack of consistency in the estimation of effective solar radiation hours will negatively affect PV plant profitability. | G25: 1
E26: 3.2.2.- Revenue estimation due to the climate change | F26: Climate change may significantly affect the estimates of PV plant profitability. | G26: 2
E27: 3.2.3.- Earthworks resources | F27: Risk of extra expenses associated with the corrective measures for land levelling. | G27: 3
E28: 3.2.4.- Flood prevention works | F28: Assessment of the risk of extra expenses due to problems associated with flood risks. | G28: 3
E29: 3.2.5.- Solution of geotechnical problems | F29: Assessment of the risk of extra expenses due to problems of geotechnical nature. | G29: 2
D30: 3.3.- Start-up permits | E30: 3.3.1.- Connection to the electric grid costs | F30: The agreement with the power supply company involves certain costs that may vary depending on the characteristics of the power connection system. | G30: 3
E31: 3.3.2.- Agreement costs with landowners | F31: Assessment of land owners willingness to sign an agreement with the land owner. | G31: 2
E32: 3.3.3.- Possibility of constructing the power connection infrastructure | F32: The connection point to the transport line is the Power Company’s responsibility. Usually the company fixes the connection point that best fits its interests. Therefore, the costs of constructing the power connection infrastruture must be estimated. | G32: 3
E33: 3.3.4.- Construction license | F33: Assessment of the risk associated with possible City Council requirements to obtain the construction license. | G33: 2
D34: 3.4.- Technology | E34: 3.4.1.- Costs due to the inadequate PV cell selection | F34: Evaluation of the costs associated with a bad choice of the photovoltaic panel. | G34: 1
E35: 3.4.2.- Costs due to inadequate inverter selection | F35: Evaluation of the costs associated with a bad choice of the photovoltaic inverter. | G35: 1
E36: 3.4.3.- Costs due to lack of consistency in the selection of support panels | F36: Evaluation of the costs associated with the repair and/or replacement of the support structure of the photovoltaic panels. | G36: 3
D37: 3.5.- Macroeconomics | E37: 3.5.1.- Bank financing | F37: Assessment of the risk for obtaining bank financing for the project. | G37: 1
E38: 3.5.2.- Changes in power demand | F38: Changes in power demand may affect the estimates of plant profitability. | G38: 2
E39: 3.5.3.- Inflation | F39: Influence of the inflation rate on the project cash-flow over the PV plant lifespan. | G39: 2
E40: 3.5.4.- Changes in energy prices | F40: Assessment of whether there is any risk of energy prices varying during the PV plant lifespan. | G40: 2
C41: GROUP | D41: SUB-GROUP | E41: RISK | F41: DESCRIPTION | G41: IMPACT
...

Sheet COST IMPACT
B1: ESTIMATING THE PROJECT RISKS IMPACT ON THE COSTS
B3: ESTIMATING THE PROJECT RISKS IMPACT ON THE COSTS | C3: GROUP | D3: SUB-GROUP | E3: RISK | F3: DESCRIPTION | G3: IMPACT | Y3: IMPACT SCALE
C4: 1.- POLITICAL RISKS | D4: 1.1.- Macroeconomics | E4: 1.1.1.- Level of political stability | F4: Government stability | G4: 2 | Y4: CRITICAL
E5: 1.1.2.- The change in energy policy | F5: Assessment of the risk associated with energy policy changes introduced by public administrations | G5: 1 | Y5: SERIOUS
D6: 1.2- Urban licenses | E6: 1.2.1.- Approval of the Local Body | F6: Political risk understood as the level of the interest in the project by the Town Mayor. Project approval is riskier if the tevel of interest is low. By contrast, projects of great interest are more likely to be approved. | G6: 3 | Y6: MODERATE
E7: 1.2.2.- Obtainig the construction license | F7: Assessment of the associated risk with the interest of the City Council to grant the license. It is a political risk as the City Council may consider the project of a higher or lower priority. | G7: 3 | Y7: MINOR
C8: GROUP | D8: SUB-GROUP | E8: RISK | F8: DESCRIPTION | G8: IMPACT | Y8: NEGLIGIBLE
C9: 2.- TECHNICAL RISKS | D9: 2.1.- Plant location | E9: 2.1.1.- Technological climate change adequacy | F9: Human activities may cause climate changes. This generates uncertainty when deciding the most suitable technology to use as the project should have a useful ife of at least 25 years, alongwhich significant climate changesmay occur. | G9: 2
E10: 2.1.2.- Flood and storm risks | F10: Assessment of flood and storm risks in the area where the PV power plant is to be built. | G10: 3
E11: 2.1.3.- Estimation of effective solar radiation | F11: There is always an error index in the estimates of solar radiation, which adds uncertainty to the project. The availability of historical statistical data of the area permits prioritizing among possible plant sites. | G11: 1
E12: 2.1.4.- Earthworks | F12: Risk of higher or lower technical problems associated with land levelling. | G12: 3
E13: 2.1.5.- Geotechnical study | F13: Assessment of the risk associated with the geotechnical problems. | G13: 3
D14: 2.2.- PV Technology | E14: 2.2.1.- New PV solar power systems | F14: Assessment of the risk in the development of new technologies. | G14: 3
E15: 2.2.2.- PV cell selection | F15: The inadequate selection of the solar panels may generate great losses. The type of solar panels will depend on the plant site. | G15: 1
E16: 2.2.3.- Inverters selection | F16: Assessment of the risk associated with the selection of the inverters. | G16: 1
E17: 2.2.4.- Selection of support pannel structure | F17: A good design and the correct choice of material of the support structure of solar panels can increase the durability of the installation and maintenance costs decrease throughout its life. | G17: 2
E18: 2.2.5.- Connection to the electric grid | F18: The connection to the electric grid requires accurate technical control systems. | G18: 2
E19: 2.2.6.- Alternative power generation systems | F19: Assessment of the risk associated with the development of new power generation systems in the site of the project, which may make public administrations reluctant to support PV. | G19: 3
C20: GROUP | D20: SUB-GROUP | E20: RISK | F20: DESCRIPTION | G20: IMPACT
C21: 3.- ECONOMIC RISKS | D21: 3.1.- Plant exploitation | E21: 3.1.1.- Plant operation cost | F21: Assessment of the risk of higher or lower operational costs. | G21: 2
E22: 3.1.2.- Corrective maintenance costs | F22: Assessment of the risk of higher or lower plant maintenance costs. | G22: 2
E23: 3.1.3.- Prevention of maintenance costs | F23: Assessment of the risk of higher or lower preventive maintenance costs. | G23: 2
E24: 3.1.4.- Performance losses | F24: Assessment of the risk of not adequately considering PV plant performance losses. This can reduce plant profitability. | G24: 1
D25: 3.2.- Plant location | E25: 3.2.1.- Errors in estimating the effective solar radiation energy | F25: Assessment of the possible errors in the estimates of effective solar radiation hours. A lack of consistency in the estimation of effective solar radiation hours will negatively affect PV plant profitability. | G25: 3
E26: 3.2.2.- Revenue estimation due to the climate change | F26: Climate change may significantly affect the estimates of PV plant profitability. | G26: 3
E27: 3.2.3.- Earthworks resources | F27: Risk of extra expenses associated with the corrective measures for land levelling. | G27: 3
E28: 3.2.4.- Flood prevention works | F28: Assessment of the risk of extra expenses due to problems associated with flood risks. | G28: 3
E29: 3.2.5.- Solution of geotechnical problems | F29: Assessment of the risk of extra expenses due to problems of geotechnical nature. | G29: 3
D30: 3.3.- Start-up permits | E30: 3.3.1.- Connection to the electric grid costs | F30: The agreement with the power supply company involves certain costs that may vary depending on the characteristics of the power connection system. | G30: 3
E31: 3.3.2.- Agreement costs with landowners | F31: Assessment of land owners willingness to sign an agreement with the land owner. | G31: 3
E32: 3.3.3.- Possibility of constructing the power connection infrastructure | F32: The connection point to the transport line is the Power Company’s responsibility. Usually the company fixes the connection point that best fits its interests. Therefore, the costs of constructing the power connection infrastruture must be estimated. | G32: 3
E33: 3.3.4.- Construction license | F33: Assessment of the risk associated with possible City Council requirements to obtain the construction license. | G33: 3
D34: 3.4.- Technology | E34: 3.4.1.- Costs due to the inadequate PV cell selection | F34: Evaluation of the costs associated with a bad choice of the photovoltaic panel. | G34: 2
E35: 3.4.2.- Costs due to inadequate inverter selection | F35: Evaluation of the costs associated with a bad choice of the photovoltaic inverter. | G35: 2
E36: 3.4.3.- Costs due to lack of consistency in the selection of support panels | F36: Evaluation of the costs associated with the repair and/or replacement of the support structure of the photovoltaic panels. | G36: 3
D37: 3.5.- Macroeconomics | E37: 3.5.1.- Bank financing | F37: Assessment of the risk for obtaining bank financing for the project. | G37: 3
E38: 3.5.2.- Changes in power demand | F38: Changes in power demand may affect the estimates of plant profitability. | G38: 3
E39: 3.5.3.- Inflation | F39: Influence of the inflation rate on the project cash-flow over the PV plant lifespan. | G39: 2
E40: 3.5.4.- Changes in energy prices | F40: Assessment of whether there is any risk of energy prices varying during the PV plant lifespan. | G40: 1
C41: GROUP | D41: SUB-GROUP | E41: RISK | F41: DESCRIPTION | G41: IMPACT
...

Sheet TIME IMPACT
B1: ESTIMATING THE IMPACT OF PROJECT RISKS ON TIME
B3: ESTIMATING THE PROJECT RISKS IMPACT ON THE TIME | C3: GROUP | D3: SUB-GROUP | E3: RISK | F3: DESCRIPTION | G3: IMPACT | Y3: IMPACT SCALE
C4: 1.- POLITICAL RISKS | D4: 1.1.- Macroeconomics | E4: 1.1.1.- Level of political stability | F4: Government stability | G4: 3 | Y4: CRITICAL
E5: 1.1.2.- The change in energy policy | F5: Assessment of the risk associated with energy policy changes introduced by public administrations | G5: 1 | Y5: SERIOUS
D6: 1.2- Urban licenses | E6: 1.2.1.- Approval of the Local Body | F6: Political risk understood as the level of the interest in the project by the Town Mayor. Project approval is riskier if the tevel of interest is low. By contrast, projects of great interest are more likely to be approved. | G6: 3 | Y6: MODERATE
E7: 1.2.2.- Obtainig the construction license | F7: Assessment of the associated risk with the interest of the City Council to grant the license. It is a political risk as the City Council may consider the project of a higher or lower priority. | G7: 3 | Y7: MINOR
C8: GROUP | D8: SUB-GROUP | E8: RISK | F8: DESCRIPTION | G8: IMPACT | Y8: NEGLIGIBLE
C9: 2.- TECHNICAL RISKS | D9: 2.1.- Plant location | E9: 2.1.1.- Technological climate change adequacy | F9: Human activities may cause climate changes. This generates uncertainty when deciding the most suitable technology to use as the project should have a useful ife of at least 25 years, alongwhich significant climate changesmay occur. | G9: 2
E10: 2.1.2.- Flood and storm risks | F10: Assessment of flood and storm risks in the area where the PV power plant is to be built. | G10: 4
E11: 2.1.3.- Estimation of effective solar radiation | F11: There is always an error index in the estimates of solar radiation, which adds uncertainty to the project. The availability of historical statistical data of the area permits prioritizing among possible plant sites. | G11: 4
E12: 2.1.4.- Earthworks | F12: Risk of higher or lower technical problems associated with land levelling. | G12: 3
E13: 2.1.5.- Geotechnical study | F13: Assessment of the risk associated with the geotechnical problems. | G13: 3
D14: 2.2.- PV Technology | E14: 2.2.1.- New PV solar power systems | F14: Assessment of the risk in the development of new technologies. | G14: 5
E15: 2.2.2.- PV cell selection | F15: The inadequate selection of the solar panels may generate great losses. The type of solar panels will depend on the plant site. | G15: 3
E16: 2.2.3.- Inverters selection | F16: Assessment of the risk associated with the selection of the inverters. | G16: 3
E17: 2.2.4.- Selection of support pannel structure | F17: A good design and the correct choice of material of the support structure of solar panels can increase the durability of the installation and maintenance costs decrease throughout its life. | G17: 3
E18: 2.2.5.- Connection to the electric grid | F18: The connection to the electric grid requires accurate technical control systems. | G18: 2
E19: 2.2.6.- Alternative power generation systems | F19: Assessment of the risk associated with the development of new power generation systems in the site of the project, which may make public administrations reluctant to support PV. | G19: 5
C20: GROUP | D20: SUB-GROUP | E20: RISK | F20: DESCRIPTION | G20: IMPACT
C21: 3.- ECONOMIC RISKS | D21: 3.1.- Plant exploitation | E21: 3.1.1.- Plant operation cost | F21: Assessment of the risk of higher or lower operational costs. | G21: 4
E22: 3.1.2.- Corrective maintenance costs | F22: Assessment of the risk of higher or lower plant maintenance costs. | G22: 4
E23: 3.1.3.- Prevention of maintenance costs | F23: Assessment of the risk of higher or lower preventive maintenance costs. | G23: 4
E24: 3.1.4.- Performance losses | F24: Assessment of the risk of not adequately considering PV plant performance losses. This can reduce plant profitability. | G24: 4
D25: 3.2.- Plant location | E25: 3.2.1.- Errors in estimating the effective solar radiation energy | F25: Assessment of the possible errors in the estimates of effective solar radiation hours. A lack of consistency in the estimation of effective solar radiation hours will negatively affect PV plant profitability. | G25: 4
E26: 3.2.2.- Revenue estimation due to the climate change | F26: Climate change may significantly affect the estimates of PV plant profitability. | G26: 3
E27: 3.2.3.- Earthworks resources | F27: Risk of extra expenses associated with the corrective measures for land levelling. | G27: 3
E28: 3.2.4.- Flood prevention works | F28: Assessment of the risk of extra expenses due to problems associated with flood risks. | G28: 3
E29: 3.2.5.- Solution of geotechnical problems | F29: Assessment of the risk of extra expenses due to problems of geotechnical nature. | G29: 3
D30: 3.3.- Start-up permits | E30: 3.3.1.- Connection to the electric grid costs | F30: The agreement with the power supply company involves certain costs that may vary depending on the characteristics of the power connection system. | G30: 2
E31: 3.3.2.- Agreement costs with landowners | F31: Assessment of land owners willingness to sign an agreement with the land owner. | G31: 3
E32: 3.3.3.- Possibility of constructing the power connection infrastructure | F32: The connection point to the transport line is the Power Company’s responsibility. Usually the company fixes the connection point that best fits its interests. Therefore, the costs of constructing the power connection infrastruture must be estimated. | G32: 3
E33: 3.3.4.- Construction license | F33: Assessment of the risk associated with possible City Council requirements to obtain the construction license. | G33: 4
D34: 3.4.- Technology | E34: 3.4.1.- Costs due to the inadequate PV cell selection | F34: Evaluation of the costs associated to a wrong selection of the photovoltaic panel. | G34: 4
E35: 3.4.2.- Costs due to inadequate inverter selection | F35: Evaluation of the costs associated to a wrong selection of the photovoltaic inverter. | G35: 4
E36: 3.4.3.- Costs due to lack of consistency in the selection of support panels | F36: Evaluation of the costs associated to the repair and/or replacement of the support structure of the photovoltaic panels. | G36: 3
D37: 3.5.- Macroeconomics | E37: 3.5.1.- Bank financing | F37: Assessment of the risk for obtaining bank financing for the project. | G37: 3
E38: 3.5.2.- Changes in power demand | F38: Changes in power demand may affect the estimates of plant profitability. | G38: 4
E39: 3.5.3.- Inflation | F39: Influence of the inflation rate on the project cash-flow over the PV plant lifespan. | G39: 4
E40: 3.5.4.- Changes in energy prices | F40: Assessment of whether there is any risk of energy prices varying during the PV plant lifespan. | G40: 4
C41: GROUP | D41: SUB-GROUP | E41: RISK | F41: DESCRIPTION | G41: IMPACT
...
